Workbook

Sheet P&L Statement
A1: Indicator | B1: Mar 26 | C1: Mar 25 | D1: Mar 24 | E1: Mar 23 | F1: Mar 22 | G1: Mar 21 | H1: Mar 20 | I1: Mar 19 | J1: Mar 18 | K1: Mar 17 | L1: Mar 16 | M1: Mar 15 | N1: Mar 14 | O1: Mar 13 | P1: Mar 12 | Q1: Mar 11 | R1: Mar 10 | S1: Mar 09 | T1: Mar 08 | U1: Mar 07 | V1: Mar 06 | W1: Mar 05 | X1: Mar 04
A2: INCOME
A3: Revenue From Operations [Gross] | B3: 18,119.45 | C3: 16,859.22 | D3: 15,938.87 | E3: 15,285.12 | F3: 13,169.04 | G3: 12,113.65 | H3: 10,820.57 | I3: 10,389.49 | J3: 9,276.17 | K3: 8,577.14 | L3: 8,097.81 | M3: 7,269.26 | N3: 6,347.85 | O3: 5,649.66 | P3: 5,005.66 | Q3: 4,230.59 | R3: 3,427.97 | S3: 3,142.89 | T3: 2,617.66 | U3: 2,317.11 | V3: 1,817.92 | W3: 1,615.45 | X3: 1,470.53
A4: Less: Excise/Sevice Tax/Other Levies | B4: 0.00 | C4: 0.00 | D4: 0.00 | E4: 0.00 | F4: 0.00 | G4: 0.00 | H4: 0.00 | I4: 0.00 | J4: 76.11 | K4: 270.02 | L4: 228.92 | M4: 168.80 | N4: 115.76 | O4: 85.28 | P4: 58.62 | Q4: 32.27 | R4: 23.27 | S4: 30.51 | T4: 29.80 | U4: 117.79 | V4: 104.58 | W4: 27.88 | X4: 30.91
A5: Revenue From Operations [Net] | B5: 18,119.45 | C5: 16,859.22 | D5: 15,938.87 | E5: 15,285.12 | F5: 13,169.04 | G5: 12,113.65 | H5: 10,820.57 | I5: 10,389.49 | J5: 9,200.06 | K5: 8,307.12 | L5: 7,868.89 | M5: 7,100.46 | N5: 6,232.09 | O5: 5,564.38 | P5: 4,947.04 | Q5: 4,198.32 | R5: 3,404.70 | S5: 3,112.38 | T5: 2,587.86 | U5: 2,199.32 | V5: 1,713.34 | W5: 1,587.57 | X5: 1,439.61
A6: Total Operating Revenues | B6: 18,445.82 | C6: 17,295.92 | D6: 16,186.08 | E6: 15,618.42 | F6: 13,371.62 | G6: 12,378.83 | H6: 10,986.68 | I6: 10,482.45 | J6: 9,304.06 | K6: 8,414.37 | L6: 7,947.90 | M6: 7,175.99 | N6: 6,307.39 | O6: 5,615.49 | P6: 4,974.19 | Q6: 4,223.52 | R6: 3,404.70 | S6: 3,112.38 | T6: 2,587.86 | U6: 2,199.32 | V6: 1,713.34 | W6: 1,587.57 | X6: 1,439.61
A7: Other Income | B7: 318.44 | C7: 250.68 | D7: 210.11 | E7: 220.59 | F7: 359.43 | G7: 292.70 | H7: 335.43 | I7: 190.52 | J7: 155.93 | K7: 144.78 | L7: 98.21 | M7: 87.53 | N7: 34.82 | O7: 55.47 | P7: 58.53 | Q7: 48.92 | R7: -0.48 | S7: 33.53 | T7: 33.17 | U7: 31.82 | V7: 33.43 | W7: 46.44 | X7: 46.42
A8: Total Revenue | B8: 18,764.26 | C8: 17,546.60 | D8: 16,396.19 | E8: 15,839.01 | F8: 13,731.05 | G8: 12,671.53 | H8: 11,322.11 | I8: 10,672.97 | J8: 9,459.99 | K8: 8,559.15 | L8: 8,046.11 | M8: 7,263.52 | N8: 6,342.21 | O8: 5,670.96 | P8: 5,032.72 | Q8: 4,272.44 | R8: 3,404.22 | S8: 3,145.91 | T8: 2,621.03 | U8: 2,231.14 | V8: 1,746.77 | W8: 1,634.01 | X8: 1,486.03
A9: EXPENSES
A10: Cost Of Materials Consumed | B10: 9,045.68 | C10: 8,608.64 | D10: 7,394.74 | E10: 7,084.09 | F10: 6,366.31 | G10: 5,509.69 | H10: 5,052.67 | I10: 4,944.77 | J10: 4,405.17 | K10: 4,342.78 | L10: 3,796.44 | M10: 3,592.99 | N10: 3,165.53 | O10: 2,890.42 | P10: 2,655.01 | Q10: 2,371.92 | R10: 1,907.00 | S10: 1,795.18 | T10: 1,507.60 | U10: 1,380.78 | V10: 955.73 | W10: 766.93 | X10: 696.62
A11: Purchase Of Stock-In Trade | B11: 2,028.01 | C11: 1,993.16 | D11: 2,033.36 | E11: 2,453.42 | F11: 2,183.41 | G11: 1,908.50 | H11: 1,543.55 | I11: 1,381.88 | J11: 1,372.46 | K11: 904.78 | L11: 833.01 | M11: 749.33 | N11: 656.78 | O11: 638.18 | P11: 529.53 | Q11: 410.31 | R11: 313.12 | S11: 162.94 | T11: 61.93 | U11: 82.14 | V11: 87.91 | W11: 136.89 | X11: 100.77
A12: Operating And Direct Expenses | B12: 0.00 | C12: 0.00 | D12: 0.00 | E12: 0.00 | F12: 0.00 | G12: 0.00 | H12: 0.00 | I12: 0.00 | J12: 0.00 | K12: 0.00 | L12: 0.00 | M12: 0.00 | N12: 0.00 | O12: 0.00 | P12: 0.00 | Q12: 0.00 | R12: 304.86 | S12: 281.37 | T12: 222.18 | U12: 188.17 | V12: 139.71 | W12: 190.32 | X12: 177.35
A13: Changes In Inventories Of FG,WIP And Stock-In Trade | B13: -21.42 | C13: -67.96 | D13: 0.01 | E13: -82.13 | F13: -73.96 | G13: -43.22 | H13: 61.51 | I13: -49.02 | J13: -4.18 | K13: -49.25 | L13: -7.12 | M13: -25.48 | N13: -12.58 | O13: -10.16 | P13: -4.79 | Q13: -17.89 | R13: -21.45 | S13: -19.44 | T13: 17.05 | U13: -34.21 | V13: -12.29 | W13: 9.72 | X13: -13.25
A14: Employee Benefit Expenses | B14: 667.47 | C14: 554.70 | D14: 565.28 | E14: 520.55 | F14: 413.56 | G14: 402.85 | H14: 368.87 | I14: 321.64 | J14: 294.87 | K14: 241.68 | L14: 209.21 | M14: 176.79 | N14: 172.45 | O14: 143.50 | P14: 145.87 | Q14: 119.93 | R14: 132.39 | S14: 120.96 | T14: 103.58 | U14: 86.96 | V14: 84.21 | W14: 85.04 | X14: 91.78
A15: Finance Costs | B15: 110.80 | C15: 137.10 | D15: 151.40 | E15: 154.95 | F15: 133.46 | G15: 97.81 | H15: 65.17 | I15: 1.54 | J15: 1.45 | K15: 1.34 | L15: 1.25 | M15: 1.21 | N15: 5.44 | O15: 37.74 | P15: 38.07 | Q15: 37.75 | R15: 4.22 | S15: 11.70 | T15: 6.40 | U15: 5.42 | V15: 2.14 | W15: 2.10 | X15: 6.05
A16: Depreciation And Amortisation Expenses | B16: 305.34 | C16: 284.67 | D16: 271.19 | E16: 195.10 | F16: 170.01 | G16: 166.77 | H16: 151.69 | I16: 135.00 | J16: 119.76 | K16: 96.43 | L16: 86.89 | M16: 117.27 | N16: 63.38 | O16: 57.08 | P16: 47.32 | Q16: 44.59 | R16: 37.54 | S16: 33.46 | T16: 29.08 | U16: 25.27 | V16: 21.72 | W16: 18.97 | X16: 22.40
A17: Other Expenses | B17: 3,335.04 | C17: 3,143.73 | D17: 3,121.87 | E17: 2,900.70 | F17: 2,393.14 | G17: 2,249.69 | H17: 2,189.39 | I17: 2,221.05 | J17: 1,825.26 | K17: 1,770.23 | L17: 1,984.54 | M17: 1,910.86 | N17: 1,728.59 | O17: 1,582.02 | P17: 1,369.34 | Q17: 1,107.77 | R17: 598.18 | S17: 576.45 | T17: 459.58 | U17: 380.52 | V17: 271.20 | W17: 228.14 | X17: 234.64
A18: Total Expenses | B18: 15,470.92 | C18: 14,654.04 | D18: 13,537.85 | E18: 13,226.68 | F18: 11,585.93 | G18: 10,292.09 | H18: 9,432.85 | I18: 8,956.86 | J18: 8,014.79 | K18: 7,307.99 | L18: 6,904.22 | M18: 6,522.97 | N18: 5,779.59 | O18: 5,338.78 | P18: 4,780.35 | Q18: 4,074.38 | R18: 3,275.86 | S18: 2,962.61 | T18: 2,407.41 | U18: 2,115.05 | V18: 1,550.33 | W18: 1,438.11 | X18: 1,326.07
A19: Profit/Loss Before Exceptional, ExtraOrdinary Items And Tax | B19: 3,293.34 | C19: 2,892.56 | D19: 2,858.34 | E19: 2,612.33 | F19: 2,145.12 | G19: 2,379.44 | H19: 1,889.26 | I19: 1,716.11 | J19: 1,445.20 | K19: 1,251.16 | L19: 1,141.89 | M19: 740.55 | N19: 562.62 | O19: 332.18 | P19: 252.37 | Q19: 198.06 | R19: 128.35 | S19: 183.30 | T19: 213.62 | U19: 116.09 | V19: 196.43 | W19: 195.90 | X19: 159.96
A20: Exceptional Items | B20: 0.00 | C20: -24.79 | D20: -2.90 | E20: 227.74 | F20: 0.00 | G20: 0.00 | H20: 19.00 | I20: 0.00 | J20: 0.00 | K20: 0.00 | L20: -10.33 | M20: 142.06 | N20: -20.00 | O20: 0.00 | P20: 0.00 | Q20: 0.00 | R20: 0.00 | S20: 0.00 | T20: 0.00 | U20: 0.00 | V20: 0.00 | W20: 0.00 | X20: 0.00
A21: Profit/Loss Before Tax | B21: 3,293.34 | C21: 2,867.77 | D21: 2,855.44 | E21: 2,840.07 | F21: 2,145.12 | G21: 2,379.44 | H21: 1,908.26 | I21: 1,716.11 | J21: 1,445.20 | K21: 1,251.16 | L21: 1,131.56 | M21: 882.61 | N21: 542.62 | O21: 332.18 | P21: 252.37 | Q21: 198.06 | R21: 128.35 | S21: 183.30 | T21: 213.62 | U21: 116.09 | V21: 196.43 | W21: 195.90 | X21: 159.96
A22: Tax Expenses-Continued Operations
A23: Current Tax | B23: 738.13 | C23: 730.63 | D23: 760.70 | E23: 708.50 | F23: 590.36 | G23: 622.53 | H23: 416.86 | I23: 581.36 | J23: 499.56 | K23: 390.20 | L23: 384.07 | M23: 285.68 | N23: 177.25 | O23: 92.85 | P23: 63.71 | Q23: 41.52 | R23: 20.67 | S23: 34.38 | T23: 35.60 | U23: 8.44 | V23: 52.08 | W23: 61.71 | X23: 69.80
A24: Less: MAT Credit Entitlement | B24: 0.00 | C24: 0.00 | D24: 0.00 | E24: 0.00 | F24: 0.00 | G24: 0.00 | H24: 0.00 | I24: 0.00 | J24: 0.00 | K24: 0.00 | L24: 0.00 | M24: 0.00 | N24: 0.00 | O24: 0.00 | P24: 0.00 | Q24: 13.91 | R24: 0.00 | S24: 0.00 | T24: 0.00 | U24: 0.00 | V24: 0.00 | W24: 0.00 | X24: 0.00
A25: Deferred Tax | B25: -6.51 | C25: 6.42 | D25: 12.69 | E25: -7.73 | F25: -48.43 | G25: -3.12 | H25: 7.10 | I25: 12.55 | J25: -2.25 | K25: 17.27 | L25: -1.60 | M25: -25.48 | N25: -4.46 | O25: 5.46 | P25: 1.92 | Q25: 12.82 | R25: -16.52 | S25: 12.32 | T25: -1.13 | U25: -2.93 | V25: -0.18 | W25: -3.75 | X25: -4.21
A26: Tax For Earlier Years | B26: 0.00 | C26: 0.00 | D26: 0.00 | E26: 0.00 | F26: 0.00 | G26: 0.00 | H26: 0.00 | I26: 0.00 | J26: 0.00 | K26: 0.00 | L26: 0.00 | M26: 0.00 | N26: 0.00 | O26: 0.00 | P26: 0.00 | Q26: 12.34 | R26: 0.00 | S26: 0.00 | T26: 0.00 | U26: 0.00 | V26: 0.00 | W26: 0.00 | X26: 0.00
A27: Total Tax Expenses | B27: 731.62 | C27: 737.05 | D27: 773.39 | E27: 700.77 | F27: 541.93 | G27: 619.41 | H27: 423.96 | I27: 593.91 | J27: 497.31 | K27: 407.47 | L27: 382.47 | M27: 260.20 | N27: 172.79 | O27: 98.31 | P27: 65.63 | Q27: 52.77 | R27: 4.27 | S27: 52.12 | T27: 41.26 | U27: 10.76 | V27: 54.29 | W27: 57.95 | X27: 65.59
A28: Profit/Loss After Tax And Before ExtraOrdinary Items | B28: 2,561.72 | C28: 2,130.72 | D28: 2,082.05 | E28: 2,139.30 | F28: 1,603.19 | G28: 1,760.03 | H28: 1,484.30 | I28: 1,122.20 | J28: 947.89 | K28: 843.69 | L28: 749.09 | M28: 622.41 | N28: 369.83 | O28: 233.87 | P28: 186.74 | Q28: 145.29 | R28: 124.09 | S28: 131.18 | T28: 172.37 | U28: 105.33 | V28: 142.14 | W28: 137.94 | X28: 94.37
A29: Profit/Loss From Continuing Operations | B29: 2,561.72 | C29: 2,130.72 | D29: 2,082.05 | E29: 2,139.30 | F29: 1,603.19 | G29: 1,760.03 | H29: 1,484.30 | I29: 1,122.20 | J29: 947.89 | K29: 843.69 | L29: 749.09 | M29: 622.41 | N29: 369.83 | O29: 233.87 | P29: 186.74 | Q29: 145.29 | R29: 116.51 | S29: 180.40 | T29: 191.00 | U29: 107.65 | V29: 146.43 | W29: 149.85 | X29: 118.80
A30: Profit/Loss For The Period | B30: 2,561.72 | C30: 2,130.72 | D30: 2,082.05 | E30: 2,139.30 | F30: 1,603.19 | G30: 1,760.03 | H30: 1,484.30 | I30: 1,122.20 | J30: 947.89 | K30: 843.69 | L30: 749.09 | M30: 622.41 | N30: 369.83 | O30: 233.87 | P30: 186.74 | Q30: 145.29 | R30: 116.51 | S30: 180.40 | T30: 191.00 | U30: 107.65 | V30: 146.43 | W30: 149.85 | X30: 118.80
A31: OTHER ADDITIONAL INFORMATION
A32: EARNINGS PER SHARE
A33: Basic EPS (Rs.) | B33: 106.35 | C33: 88.46 | D33: 86.44 | E33: 88.82 | F33: 66.56 | G33: 73.12 | H33: 61.75 | I33: 46.71 | J33: 78.96 | K33: 70.31 | L33: 62.44 | M33: 51.90 | N33: 30.87 | O33: 19.57 | P33: 15.63 | Q33: 12.16 | R33: 48.77 | S33: 75.51 | T33: 79.95 | U33: 45.06 | V33: 61.29 | W33: 62.72 | X33: 47.31
A34: Diluted EPS (Rs.) | B34: 106.35 | C34: 88.46 | D34: 86.44 | E34: 88.82 | F34: 66.56 | G34: 73.09 | H34: 61.73 | I34: 46.68 | J34: 78.92 | K34: 70.30 | L34: 62.43 | M34: 51.89 | N34: 30.87 | O34: 19.55 | P34: 15.62 | Q34: 12.16 | R34: 48.77 | S34: 75.51 | T34: 79.95 | U34: 45.06 | V34: 61.29 | W34: 62.72 | X34: 47.31
A35: VALUE OF IMPORTED AND INDIGENIOUS RAW MATERIALS STORES, SPARES AND LOOSE TOOLS
A36: Imported Raw Materials | B36: 0.00 | C36: 0.00 | D36: 0.00 | E36: 0.00 | F36: 0.00 | G36: 0.00 | H36: 0.00 | I36: 0.00 | J36: 0.00 | K36: 0.00 | L36: 4.55 | M36: 7.28 | N36: 8.09 | O36: 6.19 | P36: 1.05 | Q36: 166.35 | R36: 45.77 | S36: 0.81 | T36: 1.35 | U36: 2.80 | V36: 1.63 | W36: 29.66 | X36: 8.76
A37: Indigenous Raw Materials | B37: 0.00 | C37: 0.00 | D37: 0.00 | E37: 0.00 | F37: 0.00 | G37: 0.00 | H37: 0.00 | I37: 0.00 | J37: 0.00 | K37: 0.00 | L37: 3,791.89 | M37: 3,585.71 | N37: 3,157.44 | O37: 2,884.23 | P37: 2,653.96 | Q37: 2,205.57 | R37: 1,831.37 | S37: 1,766.25 | T37: 1,478.07 | U37: 1,348.28 | V37: 826.33 | W37: 559.61 | X37: 507.79
A38: STORES, SPARES AND LOOSE TOOLS
A39: Imported Stores And Spares | B39: 0.00 | C39: 0.00 | D39: 0.00 | E39: 0.00 | F39: 0.00 | G39: 0.00 | H39: 0.00 | I39: 0.00 | J39: 0.00 | K39: 0.00 | L39: 0.00 | M39: 0.00 | N39: 0.00 | O39: 0.00 | P39: 0.28 | Q39: 0.09 | R39: 0.10 | S39: 0.05 | T39: 0.09 | U39: 0.33 | V39: 3.98 | W39: 3.95 | X39: 0.64
A40: Indigenous Stores And Spares | B40: 0.00 | C40: 0.00 | D40: 0.00 | E40: 0.00 | F40: 0.00 | G40: 0.00 | H40: 0.00 | I40: 0.00 | J40: 0.00 | K40: 0.00 | L40: 17.56 | M40: 19.26 | N40: 18.33 | O40: 18.19 | P40: 14.04 | Q40: 11.89 | R40: 11.57 | S40: 9.78 | T40: 9.97 | U40: 8.88 | V40: 0.61 | W40: 1.58 | X40: 6.22
...

Sheet Bal Sheet
A1: Indicator | B1: Mar 26 | C1: Mar 25 | D1: Mar 24 | E1: Mar 23 | F1: Mar 22 | G1: Mar 21 | H1: Mar 20 | I1: Mar 19 | J1: Mar 18 | K1: Mar 17 | L1: Mar 16 | M1: Mar 15 | N1: Mar 14 | O1: Mar 13 | P1: Mar 12 | Q1: Mar 11 | R1: Mar 10 | S1: Mar 09 | T1: Mar 08 | U1: Mar 07 | V1: Mar 06 | W1: Mar 05 | X1: Mar 04
A2: EQUITIES AND LIABILITIES
A3: SHAREHOLDER'S FUNDS
A4: Equity Share Capital | B4: 24.09 | C4: 24.09 | D4: 24.09 | E4: 24.09 | F4: 24.09 | G4: 24.09 | H4: 24.05 | I4: 24.03 | J4: 24.01 | K4: 24.00 | L4: 24.00 | M4: 23.99 | N4: 23.99 | O4: 23.91 | P4: 23.89 | Q4: 23.89 | R4: 23.89 | S4: 23.89 | T4: 23.89 | U4: 23.89 | V4: 23.89 | W4: 23.89 | X4: 25.11
A5: Total Share Capital | B5: 24.09 | C5: 24.09 | D5: 24.09 | E5: 24.09 | F5: 24.09 | G5: 24.09 | H5: 24.05 | I5: 24.03 | J5: 24.01 | K5: 24.00 | L5: 24.00 | M5: 23.99 | N5: 23.99 | O5: 23.91 | P5: 23.89 | Q5: 23.89 | R5: 23.89 | S5: 23.89 | T5: 23.89 | U5: 23.89 | V5: 23.89 | W5: 23.89 | X5: 25.11
A6: Reserves and Surplus | B6: 4,617.14 | C6: 3,862.46 | D6: 3,503.43 | E6: 3,157.06 | F6: 2,378.45 | G6: 3,267.34 | H6: 4,216.19 | I6: 4,015.42 | J6: 3,211.27 | K6: 2,557.98 | L6: 1,676.16 | M6: 1,211.63 | N6: 829.47 | O6: 612.50 | P6: 496.15 | Q6: 427.41 | R6: 372.36 | S6: 800.65 | T6: 731.92 | U6: 590.93 | V6: 525.20 | W6: 419.63 | X6: 405.91
A7: Total Reserves and Surplus | B7: 4,617.14 | C7: 3,862.46 | D7: 3,503.43 | E7: 3,157.06 | F7: 2,378.45 | G7: 3,267.34 | H7: 4,216.19 | I7: 4,015.42 | J7: 3,211.27 | K7: 2,557.98 | L7: 1,676.16 | M7: 1,211.63 | N7: 829.47 | O7: 612.50 | P7: 496.15 | Q7: 427.41 | R7: 372.36 | S7: 800.65 | T7: 731.92 | U7: 590.93 | V7: 525.20 | W7: 419.63 | X7: 405.91
A8: Total Shareholders Funds | B8: 4,641.23 | C8: 3,886.55 | D8: 3,527.52 | E8: 3,181.15 | F8: 2,402.54 | G8: 3,319.53 | H8: 4,274.65 | I8: 4,039.45 | J8: 3,235.28 | K8: 2,581.98 | L8: 1,700.16 | M8: 1,235.62 | N8: 853.46 | O8: 636.41 | P8: 520.04 | Q8: 451.30 | R8: 396.25 | S8: 824.54 | T8: 755.81 | U8: 614.82 | V8: 549.09 | W8: 443.52 | X8: 431.03
A9: NON-CURRENT LIABILITIES
A10: Long Term Borrowings | B10: 285.83 | C10: 712.50 | D10: 904.17 | E10: 1,551.02 | F10: 698.52 | G10: 721.55 | H10: 722.13 | I10: 0.26 | J10: 0.30 | K10: 0.44 | L10: 0.49 | M10: 0.73 | N10: 0.34 | O10: 0.41 | P10: 28.15 | Q10: 430.57 | R10: 429.62 | S10: 25.16 | T10: 1.94 | U10: 1.53 | V10: 1.62 | W10: 0.00 | X10: 0.00
A11: Deferred Tax Liabilities [Net] | B11: 0.00 | C11: 0.00 | D11: 0.00 | E11: 0.00 | F11: 0.00 | G11: 7.85 | H11: 10.97 | I11: 3.87 | J11: 0.00 | K11: 0.00 | L11: 0.00 | M11: 0.00 | N11: 9.16 | O11: 13.62 | P11: 8.16 | Q11: 6.24 | R11: 24.59 | S11: 24.26 | T11: 22.64 | U11: 0.00 | V11: 15.19 | W11: 17.06 | X11: 20.25
A12: Other Long Term Liabilities | B12: 73.16 | C12: 72.54 | D12: 66.07 | E12: 60.91 | F12: 52.42 | G12: 39.32 | H12: 30.53 | I12: 27.03 | J12: 25.69 | K12: 24.30 | L12: 21.05 | M12: 19.62 | N12: 18.77 | O12: 19.18 | P12: 19.91 | Q12: 15.99 | R12: 0.00 | S12: 0.00 | T12: 0.00 | U12: 0.00 | V12: 0.00 | W12: 0.00 | X12: 0.00
A13: Long Term Provisions | B13: 0.00 | C13: 0.00 | D13: 0.00 | E13: 0.00 | F13: 0.00 | G13: 0.00 | H13: 0.00 | I13: 0.00 | J13: 0.00 | K13: 0.00 | L13: 0.00 | M13: 0.00 | N13: 0.00 | O13: 138.56 | P13: 116.82 | Q13: 122.68 | R13: 0.00 | S13: 0.00 | T13: 0.00 | U13: 0.00 | V13: 0.00 | W13: 0.00 | X13: 0.00
A14: Total Non-Current Liabilities | B14: 358.99 | C14: 785.04 | D14: 970.24 | E14: 1,611.93 | F14: 750.94 | G14: 768.72 | H14: 763.63 | I14: 31.16 | J14: 25.99 | K14: 24.74 | L14: 21.54 | M14: 20.35 | N14: 28.27 | O14: 171.77 | P14: 173.04 | Q14: 575.48 | R14: 454.21 | S14: 49.42 | T14: 24.58 | U14: 1.53 | V14: 16.81 | W14: 17.06 | X14: 20.25
A15: CURRENT LIABILITIES
A16: Short Term Borrowings | B16: 1,060.33 | C16: 504.05 | D16: 1,132.97 | E16: 1,110.76 | F16: 1,479.62 | G16: 1,075.70 | H16: 479.99 | I16: 0.00 | J16: 9.01 | K16: 0.00 | L16: 0.00 | M16: 0.00 | N16: 0.00 | O16: 189.24 | P16: 0.00 | Q16: 0.00 | R16: 0.00 | S16: 0.00 | T16: 104.16 | U16: 3.25 | V16: 7.74 | W16: 6.14 | X16: 39.19
A17: Trade Payables | B17: 1,781.87 | C17: 1,592.40 | D17: 1,513.14 | E17: 1,308.76 | F17: 1,156.62 | G17: 1,191.09 | H17: 955.98 | I17: 1,032.54 | J17: 866.36 | K17: 643.82 | L17: 659.44 | M17: 615.21 | N17: 484.68 | O17: 333.61 | P17: 336.20 | Q17: 239.68 | R17: 133.12 | S17: 2.55 | T17: 93.27 | U17: 85.82 | V17: 86.36 | W17: 73.64 | X17: 154.84
A18: Other Current Liabilities | B18: 516.10 | C18: 658.74 | D18: 675.78 | E18: 917.00 | F18: 762.07 | G18: 695.34 | H18: 596.39 | I18: 361.30 | J18: 319.61 | K18: 271.12 | L18: 191.18 | M18: 176.33 | N18: 148.37 | O18: 210.49 | P18: 518.26 | Q18: 119.38 | R18: 187.37 | S18: 263.25 | T18: 153.75 | U18: 152.29 | V18: 138.34 | W18: 132.34 | X18: 1.10
A19: Short Term Provisions | B19: 581.92 | C19: 592.94 | D19: 551.19 | E19: 508.86 | F19: 451.16 | G19: 365.63 | H19: 182.70 | I19: 188.52 | J19: 171.05 | K19: 174.48 | L19: 492.08 | M19: 410.91 | N19: 325.38 | O19: 134.40 | P19: 124.80 | Q19: 96.65 | R19: 165.02 | S19: 147.48 | T19: 100.65 | U19: 84.91 | V19: 78.33 | W19: 97.34 | X19: 59.48
A20: Total Current Liabilities | B20: 3,940.22 | C20: 3,348.13 | D20: 3,873.08 | E20: 3,845.38 | F20: 3,849.47 | G20: 3,327.76 | H20: 2,215.06 | I20: 1,582.36 | J20: 1,366.03 | K20: 1,089.42 | L20: 1,342.70 | M20: 1,202.45 | N20: 958.43 | O20: 867.74 | P20: 979.26 | Q20: 455.71 | R20: 485.51 | S20: 413.29 | T20: 451.83 | U20: 326.27 | V20: 310.77 | W20: 309.45 | X20: 254.61
A21: Total Capital And Liabilities | B21: 8,940.44 | C21: 8,019.72 | D21: 8,370.84 | E21: 8,638.46 | F21: 7,002.95 | G21: 7,416.01 | H21: 7,253.34 | I21: 5,652.97 | J21: 4,627.30 | K21: 3,696.14 | L21: 3,067.26 | M21: 2,461.99 | N21: 1,844.44 | O21: 1,683.03 | P21: 1,672.34 | Q21: 1,482.49 | R21: 1,335.97 | S21: 1,287.25 | T21: 1,232.22 | U21: 942.63 | V21: 876.67 | W21: 770.04 | X21: 705.88
A22: ASSETS
A23: NON-CURRENT ASSETS
A24: Tangible Assets | B24: 2,426.37 | C24: 2,509.41 | D24: 2,365.04 | E24: 2,220.21 | F24: 1,327.41 | G24: 1,360.02 | H24: 1,416.02 | I24: 1,283.85 | J24: 1,008.31 | K24: 812.47 | L24: 626.13 | M24: 513.25 | N24: 529.81 | O24: 437.76 | P24: 370.63 | Q24: 298.68 | R24: 276.00 | S24: 273.24 | T24: 239.33 | U24: 197.02 | V24: 140.51 | W24: 95.91 | X24: 96.77
A25: Intangible Assets | B25: 3.39 | C25: 5.96 | D25: 9.38 | E25: 12.75 | F25: 15.60 | G25: 8.54 | H25: 8.37 | I25: 7.62 | J25: 7.97 | K25: 11.60 | L25: 13.26 | M25: 12.70 | N25: 15.85 | O25: 13.92 | P25: 8.46 | Q25: 5.02 | R25: 5.50 | S25: 4.60 | T25: 1.66 | U25: 1.35 | V25: 0.05 | W25: 0.05 | X25: 30.68
A26: Capital Work-In-Progress | B26: 38.35 | C26: 81.97 | D26: 187.48 | E26: 104.47 | F26: 535.27 | G26: 111.66 | H26: 38.92 | I26: 64.91 | J26: 200.28 | K26: 29.77 | L26: 74.50 | M26: 48.22 | N26: 97.22 | O26: 128.44 | P26: 79.73 | Q26: 11.70 | R26: 11.64 | S26: 6.02 | T26: 9.69 | U26: 16.03 | V26: 11.08 | W26: 31.70 | X26: 0.86
A27: Other Assets | B27: 45.94 | C27: 47.55 | D27: 46.75 | E27: 60.50 | F27: 34.42 | G27: 35.28 | H27: 36.14 | I27: 36.13 | J27: 14.99 | K27: 15.25 | L27: 0.00 | M27: 0.00 | N27: 0.00 | O27: 0.00 | P27: 0.00 | Q27: 0.00 | R27: 0.00 | S27: 0.00 | T27: 0.00 | U27: 0.00 | V27: 0.00 | W27: 0.00 | X27: 0.00
A28: Fixed Assets | B28: 2,514.05 | C28: 2,644.89 | D28: 2,608.65 | E28: 2,397.93 | F28: 1,912.70 | G28: 1,515.50 | H28: 1,499.45 | I28: 1,392.51 | J28: 1,231.55 | K28: 869.09 | L28: 713.89 | M28: 574.17 | N28: 642.88 | O28: 580.12 | P28: 458.82 | Q28: 315.40 | R28: 293.14 | S28: 283.86 | T28: 250.68 | U28: 214.40 | V28: 151.64 | W28: 127.65 | X28: 128.30
A29: Non-Current Investments | B29: 2,066.72 | C29: 1,801.03 | D29: 1,080.04 | E29: 1,525.18 | F29: 1,221.61 | G29: 1,657.16 | H29: 2,259.11 | I29: 1,050.97 | J29: 450.65 | K29: 514.18 | L29: 551.25 | M29: 273.14 | N29: 228.95 | O29: 234.10 | P29: 218.40 | Q29: 308.94 | R29: 490.64 | S29: 423.10 | T29: 380.83 | U29: 320.05 | V29: 359.86 | W29: 330.08 | X29: 291.32
A30: Deferred Tax Assets [Net] | B30: 35.71 | C30: 29.20 | D30: 35.62 | E30: 48.31 | F30: 40.58 | G30: 0.00 | H30: 0.00 | I30: 0.00 | J30: 8.68 | K30: 6.43 | L30: 22.71 | M30: 21.11 | N30: 0.00 | O30: 0.00 | P30: 0.00 | Q30: 0.00 | R30: 31.18 | S30: 14.31 | T30: 25.02 | U30: 1.24 | V30: 13.50 | W30: 13.71 | X30: 13.14
A31: Long Term Loans And Advances | B31: 45.00 | C31: 0.00 | D31: 0.00 | E31: 150.00 | F31: 100.00 | G31: 70.73 | H31: 192.03 | I31: 15.55 | J31: 86.74 | K31: 116.52 | L31: 324.45 | M31: 127.15 | N31: 100.43 | O31: 141.31 | P31: 125.02 | Q31: 142.13 | R31: 0.00 | S31: 0.00 | T31: 0.00 | U31: 0.00 | V31: 0.00 | W31: 0.00 | X31: 0.00
A32: Other Non-Current Assets | B32: 91.28 | C32: 108.17 | D32: 126.82 | E32: 96.34 | F32: 135.00 | G32: 157.69 | H32: 97.60 | I32: 123.67 | J32: 82.16 | K32: 185.04 | L32: 37.57 | M32: 37.12 | N32: 12.12 | O32: 12.12 | P32: 12.12 | Q32: 12.12 | R32: 0.00 | S32: 26.64 | T32: 23.23 | U32: 25.58 | V32: 16.06 | W32: 34.24 | X32: 46.30
A33: Total Non-Current Assets | B33: 4,752.76 | C33: 4,583.29 | D33: 3,851.13 | E33: 4,217.76 | F33: 3,409.89 | G33: 3,401.08 | H33: 4,048.19 | I33: 2,582.70 | J33: 1,859.78 | K33: 1,691.26 | L33: 1,649.87 | M33: 1,032.69 | N33: 984.38 | O33: 967.65 | P33: 814.36 | Q33: 778.59 | R33: 814.95 | S33: 747.91 | T33: 679.76 | U33: 561.26 | V33: 541.06 | W33: 505.67 | X33: 479.06
A34: CURRENT ASSETS
A35: Current Investments | B35: 1,617.02 | C35: 1,071.12 | D35: 1,690.68 | E35: 1,798.47 | F35: 802.50 | G35: 1,292.96 | H35: 882.06 | I35: 594.70 | J35: 735.48 | K35: 85.73 | L35: 343.63 | M35: 387.90 | N35: 144.04 | O35: 45.50 | P35: 210.54 | Q35: 236.06 | R35: 0.00 | S35: 0.00 | T35: 0.00 | U35: 0.00 | V35: 0.00 | W35: 0.00 | X35: 0.00
A36: Inventories | B36: 1,219.92 | C36: 1,128.90 | D36: 1,075.44 | E36: 1,074.62 | F36: 1,251.64 | G36: 991.28 | H36: 633.53 | I36: 718.89 | J36: 594.58 | K36: 602.61 | L36: 384.01 | M36: 345.74 | N36: 366.86 | O36: 331.49 | P36: 382.28 | Q36: 311.20 | R36: 268.34 | S36: 253.63 | T36: 301.53 | U36: 214.94 | V36: 184.80 | W36: 134.22 | X36: 122.25
A37: Trade Receivables | B37: 404.74 | C37: 379.63 | D37: 347.05 | E37: 278.42 | F37: 253.85 | G37: 198.36 | H37: 242.23 | I37: 350.96 | J37: 230.32 | K37: 126.41 | L37: 106.70 | M37: 70.98 | N37: 53.69 | O37: 77.12 | P37: 52.14 | Q37: 57.26 | R37: 39.49 | S37: 49.61 | T37: 46.33 | U37: 28.61 | V37: 20.85 | W37: 44.31 | X37: 19.92
A38: Cash And Cash Equivalents | B38: 90.82 | C38: 105.64 | D38: 297.50 | E38: 63.85 | F38: 52.29 | G38: 110.80 | H38: 39.16 | I38: 40.48 | J38: 97.25 | K38: 53.55 | L38: 24.80 | M38: 186.67 | N38: 65.78 | O38: 64.48 | P38: 30.94 | Q38: 28.75 | R38: 23.36 | S38: 40.80 | T38: 43.77 | U38: 48.65 | V38: 35.34 | W38: 16.31 | X38: 7.08
A39: Short Term Loans And Advances | B39: 121.00 | C39: 50.00 | D39: 460.00 | E39: 560.00 | F39: 698.00 | G39: 946.09 | H39: 1,075.73 | I39: 1,121.41 | J39: 820.41 | K39: 791.94 | L39: 558.25 | M39: 438.01 | N39: 229.69 | O39: 196.79 | P39: 182.08 | Q39: 70.63 | R39: 189.83 | S39: 195.30 | T39: 160.83 | U39: 89.00 | V39: 94.07 | W39: 69.33 | X39: 77.13
A40: OtherCurrentAssets | B40: 734.18 | C40: 701.14 | D40: 649.04 | E40: 645.34 | F40: 534.78 | G40: 475.44 | H40: 332.44 | I40: 243.83 | J40: 289.48 | K40: 344.64 | L40: 0.00 | M40: 0.00 | N40: 0.00 | O40: 0.00 | P40: 0.00 | Q40: 0.00 | R40: 0.00 | S40: 0.00 | T40: 0.01 | U40: 0.17 | V40: 0.56 | W40: 0.18 | X40: 0.44
...

Sheet Table I
A1: Liquidity Ratio | B1: 2025-26 | C1: 2024-25 | D1: 2023-24 | E1: 2022-23 | F1: 2021-22
A2: a)Current Ratio- | B2: 1.0628036 | C2: 1.0263729 | D2: 1.166955 | E2: 1.1496133 | F2: 0.93339083
A3: b)Liquid Ratio- | B3: 0.75319652 | C3: 0.68919964 | D3: 0.8892845 | E3: 0.87015588 | F3: 0.60824477
A5: Profitability Ratios | B5: 2025-26 | C5: 2024-25 | D5: 2023-24 | E5: 2022-23 | F5: 2021-22
A6: a)Net Profit Ration (before tax) | B6: 18.175717 | C6: 17.010099 | D6: 17.914946 | E6: 18.58062 | F6: 16.289114
A7: b)Net Profit Ration (after tax) | B7: 14.137957 | C7: 12.638307 | D7: 13.06272 | E7: 13.995965 | F7: 12.173932
A8: c)RoE | B8: 55.194851 | C8: 54.822915 | D8: 59.023053 | E8: 67.249265 | F8: 66.728962
A9: d)RoI | B9: 65.863902 | C9: 61.387451 | D9: 63.485824 | E9: 59.253549 | F9: 68.023897
A11: Solvency Ratios | B11: 2025-26 | C11: 2024-25 | D11: 2023-24 | E11: 2022-23 | F11: 2021-22
A12: a)Debt-Equity Ratio | B12: 0.077348031 | C12: 0.20198891 | D12: 0.27504876 | E12: 0.50671298 | F12: 0.31256087
A13: b)Proprietory Ratio | B13: 0.51912769 | C13: 0.48462415 | D13: 0.42140574 | E13: 0.3682543 | F13: 0.34307542
A15: Efficiency | B15: 2025-26 | C15: 2024-25 | D15: 2023-24 | E15: 2022-23 | F15: 2021-22
A16: a)Inventory Turnover Ratio | B16: 16.157019 | C16: 14.4947 | D16: 14.826442 | E16: 13.868205 | F16: 11.213324
A17: b)Working Capital Turnover Ratio | B17: 73.221733 | C17: 190.93114 | D17: 24.649135 | E17: 26.568032 | F17: -51.359307

Sheet Table II
C1: Comparative Financial Ratio Analysis
A2: Ratios | B2: 2025-26 | C2: 2024-25 | D2: Change in Ratio | E2: Analysis
A3: Liquidity Ratio
A4: a)Current Ratio- | B4: ='Table I'!B2 -> 1.0628036 | C4: ='Table I'!C2 -> 1.0263729 | D4: =B4-C4 -> 0.036430669 | E4: Short-term liquidity improved
A5: b)Liquid Ratio- | B5: ='Table I'!B3 -> 0.75319652 | C5: ='Table I'!C3 -> 0.68919964 | D5: =B5-C5 -> 0.063996879 | E5: Immediate liquidity improved
A7: Profitability Ratios
A8: a)Net Profit Ration (before tax) | B8: ='Table I'!B6 -> 18.175717 | C8: ='Table I'!C6 -> 17.010099 | D8: =B8-C8 -> 1.1656183 | E8: Profitability improved
A9: b)Net Profit Ration (after tax) | B9: ='Table I'!B7 -> 14.137957 | C9: ='Table I'!C7 -> 12.638307 | D9: =B9-C9 -> 1.4996496 | E9: Net profitability improved
A10: c)RoE | B10: ='Table I'!B8 -> 55.194851 | C10: ='Table I'!C8 -> 54.822915 | D10: =B10-C10 -> 0.37193644 | E10: Shareholder return slightly improved
A11: d)RoI | B11: ='Table I'!B9 -> 65.863902 | C11: ='Table I'!C9 -> 61.387451 | D11: =B11-C11 -> 4.4764515 | E11: Return generation improved
A13: Solvency Ratios
A14: a)Debt-Equity Ratio | B14: ='Table I'!B12 -> 0.077348031 | C14: ='Table I'!C12 -> 0.20198891 | D14: =B14-C14 -> -0.12464088 | E14: Debt dependence reduced
A15: b)Proprietory Ratio | B15: ='Table I'!B13 -> 0.51912769 | C15: ='Table I'!C13 -> 0.48462415 | D15: =B15-C15 -> 0.034503542 | E15: Equity based financing strengthened
A17: Efficiency
A18: a)Inventory Turnover Ratio | B18: ='Table I'!B16 -> 16.157019 | C18: ='Table I'!C16 -> 14.4947 | D18: =B18-C18 -> 1.6623189 | E18: Inventory efficiency improved
A19: b)Working Capital Turnover Ratio | B19: ='Table I'!B17 -> 73.221733 | C19: ='Table I'!C17 -> 190.93114 | D19: =B19-C19 -> -117.70941 | E19: Major concern
A21: Overall, Britannia showed improved profitability, lower debt dependence and better inventory efficiency. However, the major concern was the sharp decline in working capital turnover, while liquidity remained relatively tight."

Sheet Dashboards
D1: Charts Analysis of 5 years of Britannia Industries Ltd
